Traceback (most recent call last):
  File "/Users/aaron/mambaforge/envs/pymc3_test/lib/python3.9/site-packages/jupyter_cache/executors/utils.py", line 51, in single_nb_execution
    executenb(
  File "/Users/aaron/mambaforge/envs/pymc3_test/lib/python3.9/site-packages/nbclient/client.py", line 1093, in execute
    return NotebookClient(nb=nb, resources=resources, km=km, **kwargs).execute()
  File "/Users/aaron/mambaforge/envs/pymc3_test/lib/python3.9/site-packages/nbclient/util.py", line 84, in wrapped
    return just_run(coro(*args, **kwargs))
  File "/Users/aaron/mambaforge/envs/pymc3_test/lib/python3.9/site-packages/nbclient/util.py", line 62, in just_run
    return loop.run_until_complete(coro)
  File "/Users/aaron/mambaforge/envs/pymc3_test/lib/python3.9/asyncio/base_events.py", line 642, in run_until_complete
    return future.result()
  File "/Users/aaron/mambaforge/envs/pymc3_test/lib/python3.9/site-packages/nbclient/client.py", line 559, in async_execute
    await self.async_execute_cell(
  File "/Users/aaron/mambaforge/envs/pymc3_test/lib/python3.9/site-packages/nbclient/client.py", line 854, in async_execute_cell
    self._check_raise_for_error(cell, exec_reply)
  File "/Users/aaron/mambaforge/envs/pymc3_test/lib/python3.9/site-packages/nbclient/client.py", line 756, in _check_raise_for_error
    raise CellExecutionError.from_cell_and_msg(cell, exec_reply_content)
nbclient.exceptions.CellExecutionError: An error occurred while executing the following cell:
------------------
# this will remove the first 500 samples
burned = trace.sel(draw=slice(500, None))
------------------

[0;31m---------------------------------------------------------------------------[0m
[0;31mAttributeError[0m                            Traceback (most recent call last)
Input [0;32mIn [4][0m, in [0;36m<module>[0;34m[0m
[1;32m      1[0m [38;5;66;03m# this will remove the first 500 samples[39;00m
[0;32m----> 2[0m burned [38;5;241m=[39m [43mtrace[49m[38;5;241;43m.[39;49m[43msel[49m(draw[38;5;241m=[39m[38;5;28mslice[39m([38;5;241m500[39m, [38;5;28;01mNone[39;00m))

File [0;32m~/mambaforge/envs/pymc3_test/lib/python3.9/site-packages/pymc3/backends/base.py:367[0m, in [0;36mMultiTrace.__getattr__[0;34m(self, name)[0m
[1;32m    365[0m [38;5;28;01mif[39;00m name [38;5;129;01min[39;00m [38;5;28mself[39m[38;5;241m.[39mstat_names:
[1;32m    366[0m     [38;5;28;01mreturn[39;00m [38;5;28mself[39m[38;5;241m.[39mget_sampler_stats(name)
[0;32m--> 367[0m [38;5;28;01mraise[39;00m [38;5;167;01mAttributeError[39;00m([38;5;124m"[39m[38;5;124m'[39m[38;5;132;01m{}[39;00m[38;5;124m'[39m[38;5;124m object has no attribute [39m[38;5;124m'[39m[38;5;132;01m{}[39;00m[38;5;124m'[39m[38;5;124m"[39m[38;5;241m.[39mformat([38;5;28mtype[39m([38;5;28mself[39m)[38;5;241m.[39m[38;5;18m__name__[39m, name))

[0;31mAttributeError[0m: 'MultiTrace' object has no attribute 'sel'
AttributeError: 'MultiTrace' object has no attribute 'sel'

